Workbook

Sheet Model
B2: GrowthPath — Per-Client API Cost & Margin Model
B3: Single re-scan cadence · all costs are live formulas · edit the yellow input cells
B5: API COST CONSTANTS (per call — edit if pricing changes)
B6: Rank call cost — Maps (per ZCTA) | C6: 0.002 | D6: DFS Maps SERP · Decisions v4.31
B7: Rank call cost — Local Finder (per ZCTA) | C7: 0.002 | D7: DFS Local Finder · same as Maps
B8: GBP signal bundle (per scan, flat) | C8: 0.015 | D8: my_business_info + updates + reviews
B9: On-page / PageSpeed (per scan, flat) | C9: 0.00425 | D9: DFS OnPage browser tier · per page
B10: Domain Authority / Moz (per scan, flat) | C10: 0.01 | D10: Moz bulk DA + RDs
B11: Citations / listings check (per scan) | C11: 0.01 | D11: DFS business_listings search
B12: AI cost — per chat message (cached) | C12: 0.02 | D12: Sonnet w/ prompt caching · ~$0.01-0.03
B13: AI cost — monthly narrative (per gen) | C13: 0.1 | D13: one generation/month · $0.05-0.15
B15: SCAN COMPOSITION (fixed structure — every keyword)
B16: Every keyword is scanned on 2 surfaces (Maps + Local Finder) × 2 intent variants (near-me + city-modifier) = 4 rank calls per keyword PER ZCTA.
B17: Surfaces per keyword (Maps + LF) | C17: 2
B18: Variants per keyword (near-me + city) | C18: 2
B19: Rank calls per keyword, per ZCTA | C19: =C17*C18 -> 4
B21: CLIENT VARIABLES ◄ THE LEVERS — change these
B22: Keywords scanned | C22: 5 | D22: owner-defined + discovered
B23: ZCTAs in grid | C23: 20 | D23: near-me cap 5 + city target 5
B24: Scans per year (single cadence) | C24: 52 | D24: 1=annual, 4=quarterly, 12=monthly, 52=weekly
B25: AI chat messages per month | C25: 100 | D25: tier allotment: 50 / 100 / 200
B26: Months active in program | C26: 12 | D26: graduation model = 12
B28: COST PER FULL SCAN (one complete scan event)
B29: Rank calls per scan | C29: =$C$22*$C$19*$C$23 -> 400
B30: Rank-call cost per scan | C30: =($C$22*$C$6*$C$23)+($C$22*$C$7*$C$23) -> 0.4
B31: Flat signal cost per scan (GBP+OnPage+DA+Cit) | C31: =$C$8+$C$9+$C$10+$C$11 -> 0.03925
B32: TOTAL COST PER FULL SCAN | C32: =C30+C31 -> 0.43925
B34: ANNUAL COST PER CLIENT (over the program)
B35: AI chat messages per year | C35: =$C$25*$C$26 -> 1200
B36: AI chat cost per year | C36: =C35*$C$12 -> 24
B37: Monthly narrative cost per year | C37: =$C$26*$C$13 -> 1.2
B38: Scan cost per year (scans × cost/scan) | C38: =$C$24*$C$32 -> 22.841
B39: TOTAL API COST PER CLIENT / YEAR | C39: =C36+C37+C38 -> 48.041
B41: MARGIN BY TIER (price − annual cost)
B42: Tier | C42: Price/yr | D42: API cost/yr | E42: Gross $ | F42: Margin % | G42: Cost % of rev
B43: Standard | C43: 149 | D43: =$C$39 -> 48.041 | E43: =C43-D43 -> 100.959 | F43: =E43/C43 -> 0.67757718 | G43: =D43/C43 -> 0.32242282
B44: Professional | C44: 199 | D44: =$C$39 -> 48.041 | E44: =C44-D44 -> 150.959 | F44: =E44/C44 -> 0.75858794 | G44: =D44/C44 -> 0.24141206
B45: Growth | C45: 249 | D45: =$C$39 -> 48.041 | E45: =C45-D45 -> 200.959 | F45: =E45/C45 -> 0.80706426 | G45: =D45/C45 -> 0.19293574
B47: BREAK-EVEN (max full scans/yr before a tier goes underwater)
B48: How many full scans/yr can each tier absorb before API cost = price? Holds AI cost fixed; solves scans against the scan cost only.
...

Sheet Tiers
B2: GrowthPath Tiers — Cost & Margin
B3: Three live tiers · weekly tracking (52 scans/yr) · edit yellow cells to tune
C5: Basic $149 | D5: Premium $199 | E5: Elite $249
B6: Price / year | C6: 149 | D6: 199 | E6: 249
B7: Keywords | C7: 3 | D7: 5 | E7: 5
B8: ZCTAs in grid | C8: 10 | D8: 20 | E8: 20
B9: Scans per year (weekly) | C9: 52 | D9: 52 | E9: 52
B10: AI msgs / month | C10: 50 | D10: 100 | E10: 100
B11: Months active | C11: 12 | D11: 12 | E11: 12
B12: GA4 + GSC integrations (1=yes) | C12: 0 | D12: 0 | E12: 1
B14: Annual cost build-up
B15: Cost per full scan | C15: =(C7*Model!C6*C8)+(C7*Model!C7*C8)+Model!C8+Model!C9+Model!C10+Model!C11 -> 0.15925 | D15: =(D7*Model!C6*D8)+(D7*Model!C7*D8)+Model!C8+Model!C9+Model!C10+Model!C11 -> 0.43925 | E15: =(E7*Model!C6*E8)+(E7*Model!C7*E8)+Model!C8+Model!C9+Model!C10+Model!C11 -> 0.43925
B16: Scan cost / year | C16: =C9*C15 -> 8.281 | D16: =D9*D15 -> 22.841 | E16: =E9*E15 -> 22.841
B17: AI chat / year | C17: =C10*C11*Model!C12 -> 12 | D17: =D10*D11*Model!C12 -> 24 | E17: =E10*E11*Model!C12 -> 24
B18: Narrative / year | C18: =C11*Model!C13 -> 1.2 | D18: =D11*Model!C13 -> 1.2 | E18: =E11*Model!C13 -> 1.2
B19: GA4+GSC token add (if enabled) | C19: =C12*'GA4-GSC Tokens'!C24 -> 0 | D19: =D12*'GA4-GSC Tokens'!C24 -> 0 | E19: =E12*'GA4-GSC Tokens'!C24 -> 1.836
B20: TOTAL COST / CLIENT / YEAR | C20: =C16+C17+C18+C19 -> 21.481 | D20: =D16+D17+D18+D19 -> 48.041 | E20: =E16+E17+E18+E19 -> 49.877
B22: Margin (per-tier price)
B23: Gross $ / client / yr | C23: =C6-C20 -> 127.519 | D23: =D6-D20 -> 150.959 | E23: =E6-E20 -> 199.123
B24: Margin % | C24: =C23/C6 -> 0.85583221 | D24: =D23/D6 -> 0.75858794 | E24: =E23/E6 -> 0.79969076
B25: Cost as % of revenue | C25: =C20/C6 -> 0.14416779 | D25: =D20/D6 -> 0.24141206 | E25: =E20/E6 -> 0.20030924
B27: Green = pulled from Model + GA4-GSC Tokens sheets · Blue = editable input. All tiers: weekly performance tracking + monthly AI audit/summary.

Sheet GA4-GSC Tokens
B2: Growth Tier — Incremental Token Cost of GA4 + GSC
B3: OAuth + data pulls cost $0 in tokens. Cost = larger cached context + richer narrative + chat utilization.
B5: SONNET TOKEN PRICING (per 1M tokens — edit if pricing changes)
B6: Input — uncached ($ / 1M tokens) | C6: 3 | D6: Sonnet standard input
B7: Input — cache WRITE ($ / 1M) | C7: 3.75 | D7: 1.25x input · paid once per refresh
B8: Input — cache READ ($ / 1M) | C8: 0.3 | D8: 0.1x input · ~90% cheaper
B9: Output ($ / 1M tokens) | C9: 15 | D9: generated text · not cacheable
B11: INCREMENTAL TOKEN SIZES ◄ the GA4/GSC additions only
B12: Added GA4+GSC context (tokens, cached) | C12: 4000 | D12: traffic + keyword data block added to prefix
B13: Context refreshes per year | C13: 12 | D13: GA4/GSC update daily; assume monthly cache refresh
B14: Added output per monthly narrative (tokens) | C14: 600 | D14: extra GA4/GSC interpretation in narrative
B15: Added input per chat msg — cache read (tokens) | C15: 4000 | D15: same context, read from cache each msg
B16: Extra chat msgs/yr driven by GA4/GSC | C16: 240 | D16: e.g. +20/mo utilization within 200 cap
B17: Added output per extra chat msg (tokens) | C17: 350 | D17: answer length
B19: INCREMENTAL ANNUAL COST PER CLIENT
B20: Cache-write cost (context × refreshes) | C20: =($C$12*$C$13/1000000)*$C$7 -> 0.18
B21: Narrative extra output (12 × added tokens) | C21: =(12*$C$14/1000000)*$C$9 -> 0.108
B22: Chat context cache-reads (extra msgs × ctx) | C22: =($C$16*$C$15/1000000)*$C$8 -> 0.288
B23: Chat extra output (extra msgs × output) | C23: =($C$16*$C$17/1000000)*$C$9 -> 1.26
B24: TOTAL ADDED TOKEN COST / CLIENT / YEAR | C24: =C20+C21+C22+C23 -> 1.836
B26: IMPACT ON GROWTH TIER ($249)
B27: Metric | C27: Before | D27: After GA4/GSC | E27: Delta
B28: API cost / client / yr | C28: =Model!C39 -> 48.041 | D28: =Model!C39+$C$24 -> 49.877 | E28: =$C$24 -> 1.836
B29: Margin $ @ $249 | C29: =249-Model!C39 -> 200.959 | D29: =249-(Model!C39+$C$24) -> 199.123 | E29: =-$C$24 -> -1.836
B30: Margin % @ $249 | C30: =(249-Model!C39)/249 -> 0.80706426 | D30: =(249-(Model!C39+$C$24))/249 -> 0.79969076 | E30: =D30-C30 -> -0.007373494
B32: Note: GA4/GSC OAuth and data retrieval from Google cost $0 in Anthropic tokens. The only token cost is feeding that data into Claude for narrative + chat. Cache reads keep the recurring chat cost near-zero; the monthly narrative output is the main driver.
B34: Blue = editable · Black = formula · GrowthPath Analytics · Confidential · June 2026
